<?xml version="1.0"?>
<robot name="snakebot" xmlns:xacro="http://www.ros.org/wiki/xacro">
        <!-- Put here the robot description -->
        
        
	
	<macro name="cylinder_inertia" params="m r h">
		<inertia  ixx="${m*(3*r*r+h*h)/12}" ixy = "0" ixz = "0"
		  iyy="${m*(3*r*r+h*h)/12}" iyz = "0"
		  izz="${m*r*r/2}"
		/>
	</macro>

	<macro name="box_inertia" params="m x y z">
		<inertia  ixx="${m*(y*y+z*z)/12}" ixy = "0" ixz = "0"
		  iyy="${m*(x*x+z*z)/12}" iyz = "0"
		  izz="${m*(x*x+z*z)/12}"
		/>
	</macro>

	<macro name="sphere_inertia" params="m r">
		<inertia  ixx="${2*m*r*r/5}" ixy = "0" ixz = "0"
		  iyy="${2*m*r*r/5}" iyz = "0"
		  izz="${2*m*r*r/5}"
		/>
	</macro>
	
	<macro name="body_first" params="num nextNum">
		<link name='body_0${num}'>
		<collision> 
		  <origin xyz="0 0 ${chassisHeight/2}" rpy="0 0 0"/> 
		  <geometry> 
		    <box size="${chassisLength} ${chassisWidth} ${chassisHeight}"/> 
		  </geometry> 
		</collision>
		<visual> 
		  <origin xyz="0 0 ${chassisHeight/2}" rpy="0 0 0"/>
		  <geometry> 
		    <box size="${chassisLength} ${chassisWidth} ${chassisHeight}"/>
		  </geometry> 
		  <material name="red"/>
		</visual>
		<inertial> 
		  <origin xyz="0 0 ${chassisHeight/2}" rpy="0 0 0"/>
    	<mass value="${chassisMass}"/> 
    	<box_inertia m="${chassisMass}" x="${chassisLength}" y="${chassisWidth}" z="${chassisHeight}"/>
  	</inertial>
	</link>
	
	<gazebo reference="body_0${num}">
		<self_collide>true</self_collide>
		<mu1>0.01</mu1>
  	<mu2>1.0</mu2>
		<fdir1>1 0 0</fdir1>
  	<material>Gazebo/Orange</material>
		  
		<sensor name="body_0${num}_bumper" type="contact">
			<always_on>true</always_on>
	    <update_rate>30</update_rate>
	    <contact>
	      <collision>body_0${num}_collision</collision>
	    </contact>
			<plugin filename="libgazebo_ros_bumper.so" name="bumper_plugin_0${num}">
				<bumperTopicName>bumper_0${num}</bumperTopicName>
				<frameName>body_0${num}</frameName>
			</plugin>
		</sensor>
	</gazebo>



	<gazebo>
		<plugin name="gazebo_ros_control" filename="libgazebo_ros_control.so">
		  <robotNamespace>/snakebot</robotNamespace>
		</plugin>
	</gazebo>

	<joint name="joint_0${num}" type="continuous">
		<parent link="body_0${num}"/>
		<child link="body_0${nextNum}"/>
		<origin xyz="${chassisLength/2 + jointOffset} 0 ${chassisHeight/2}" rpy="0 0 0" />
	 	<axis xyz="0 0 1" rpy="0 0 0" />
		<limit effort="100" velocity="1"/>
		<joint_properties damping="100.0" friction="0.0"/>
	</joint>

	<transmission name="trans_0${num}">
		<type>transmission_interface/SimpleTransmission</type>
		<joint name="joint_0${num}">
			<hardwareInterface>EffortJointInterface</hardwareInterface>
		</joint>
		<actuator name="motor_0${num}">
		  <hardwareInterface>EffortJointInterface</hardwareInterface>
		  <mechanicalReduction>10</mechanicalReduction>
		</actuator>
	</transmission>
	
	
	</macro>

	<macro name="body_upTo9" params="num nextNum">
	
	<link name="body_0${num}">
		<collision> 
		  <origin xyz="${chassisLength/2 + jointOffset} 0 0" rpy="0 0 0"/> 
		  <geometry> 
		    <box size="${chassisLength} ${chassisWidth} ${chassisHeight}"/> 
		  </geometry> 
		</collision>
		<visual> 
		  <origin xyz="${chassisLength/2 + jointOffset} 0 0" rpy="0 0 0"/> 
		  <geometry> 
		    <box size="${chassisLength} ${chassisWidth} ${chassisHeight}"/> 
		  </geometry> 
		  <material name="green"/>
		</visual>
		<inertial> 
		  <origin xyz="${chassisLength/2 + jointOffset} 0 0" rpy="0 0 0"/> 
    	<mass value="${chassisMass}"/> 
    	<box_inertia m="${chassisMass}" x="${chassisLength}" y="${chassisWidth}" z="${chassisHeight}"/>
  	</inertial>
	</link>
	
	<gazebo reference="body_0${num}">
  	<mu1 value="0.3"/>
  	<mu2 value="0.3"/>
  	<kp  value="10000000.0" />
  	<kd  value="1.0" />
  	<fdir1 value="1 0 0"/>
  	<material>Gazebo/Orange</material>
  	
  	<sensor name="body_0${num}_bumper" type="contact">
			<always_on>true</always_on>
	    <update_rate>30</update_rate>
	    <contact>
	      <collision>body_0${num}_collision</collision>
	    </contact>
			<plugin filename="libgazebo_ros_bumper.so" name="bumper_plugin_0${num}">
				<bumperTopicName>bumper_0${num}</bumperTopicName>
				<frameName>body_0${num}</frameName>
			</plugin>
		</sensor>
	</gazebo>
	
	<joint name="joint_0${num}" type="continuous">
		<parent link="body_0${num}"/>
		<child link="body_0${nextNum}"/>
		<origin xyz="${chassisLength+2*jointOffset} 0 0" rpy="0 0 0" />
	 	<axis xyz="0 0 1" rpy="0 0 0" />
		<limit effort="100" velocity="1"/>
		<joint_properties damping="100.0" friction="0.0"/>
	</joint>

	<transmission name="trans_0${num}">
		<type>transmission_interface/SimpleTransmission</type>
		<joint name="joint_0${num}">
			<hardwareInterface>EffortJointInterface</hardwareInterface>
		</joint>
		<actuator name="motor_0${num}">
		  <hardwareInterface>EffortJointInterface</hardwareInterface>
		  <mechanicalReduction>10</mechanicalReduction>
		</actuator>
	</transmission>

	</macro>
	
		<macro name="body_9" params="num nextNum">
	
	<link name="body_0${num}">
		<collision> 
		  <origin xyz="${chassisLength/2 + jointOffset} 0 0" rpy="0 0 0"/> 
		  <geometry> 
		    <box size="${chassisLength} ${chassisWidth} ${chassisHeight}"/> 
		  </geometry> 
		</collision>
		<visual> 
		  <origin xyz="${chassisLength/2 + jointOffset} 0 0" rpy="0 0 0"/> 
		  <geometry> 
		    <box size="${chassisLength} ${chassisWidth} ${chassisHeight}"/> 
		  </geometry> 
		  <material name="green"/>
		</visual>
		<inertial> 
		  <origin xyz="${chassisLength/2 + jointOffset} 0 0" rpy="0 0 0"/> 
    	<mass value="${chassisMass}"/> 
    	<box_inertia m="${chassisMass}" x="${chassisLength}" y="${chassisWidth}" z="${chassisHeight}"/>
  	</inertial>
	</link>
	
	<gazebo reference="body_0${num}">
  	<mu1 value="0.3"/>
  	<mu2 value="0.3"/>
  	<kp  value="10000000.0" />
  	<kd  value="1.0" />
  	<fdir1 value="1 0 0"/>
  	<material>Gazebo/Orange</material>
  	
  	<sensor name="body_0${num}_bumper" type="contact">
			<always_on>true</always_on>
	    <update_rate>30</update_rate>
	    <contact>
	      <collision>body_0${num}_collision</collision>
	    </contact>
			<plugin filename="libgazebo_ros_bumper.so" name="bumper_plugin_0${num}">
				<bumperTopicName>bumper_0${num}</bumperTopicName>
				<frameName>body_0${num}</frameName>
			</plugin>
		</sensor>
	</gazebo>
	
	<joint name="joint_0${num}" type="continuous">
		<parent link="body_0${num}"/>
		<child link="body_${nextNum}"/>
		<origin xyz="${chassisLength+2*jointOffset} 0 0" rpy="0 0 0" />
	 	<axis xyz="0 0 1" rpy="0 0 0" />
		<limit effort="100" velocity="1"/>
		<joint_properties damping="100.0" friction="0.0"/>
	</joint>

	<transmission name="trans_0${num}">
		<type>transmission_interface/SimpleTransmission</type>
		<joint name="joint_0${num}">
			<hardwareInterface>EffortJointInterface</hardwareInterface>
		</joint>
		<actuator name="motor_0${num}">
		  <hardwareInterface>EffortJointInterface</hardwareInterface>
		  <mechanicalReduction>10</mechanicalReduction>
		</actuator>
	</transmission>

	</macro>
	
	<macro name="body_last_upTo9" params="num">
	
	<link name="body_0${num}">
		<collision> 
		  <origin xyz="${chassisLength/2 + jointOffset} 0 0" rpy="0 0 0"/> 
		  <geometry> 
		    <box size="${chassisLength} ${chassisWidth} ${chassisHeight}"/> 
		  </geometry> 
		</collision>
		<visual> 
		  <origin xyz="${chassisLength/2 + jointOffset} 0 0" rpy="0 0 0"/> 
		  <geometry> 
		    <box size="${chassisLength} ${chassisWidth} ${chassisHeight}"/> 
		  </geometry> 
		  <material name="green"/>
		</visual>
		<inertial> 
		  <origin xyz="${chassisLength/2 + jointOffset} 0 0" rpy="0 0 0"/> 
    	<mass value="${chassisMass}"/> 
    	<box_inertia m="${chassisMass}" x="${chassisLength}" y="${chassisWidth}" z="${chassisHeight}"/>
  	</inertial>
	</link>
	
	<gazebo reference="body_0${num}">
  	<mu1 value="0.3"/>
  	<mu2 value="0.3"/>
  	<kp  value="10000000.0" />
  	<kd  value="1.0" />
  	<fdir1 value="1 0 0"/>
  	<material>Gazebo/Red</material>
  	
  	<sensor name="body_0${num}_bumper" type="contact">
			<always_on>true</always_on>
	    <update_rate>30</update_rate>
	    <contact>
	      <collision>body_0${num}_collision</collision>
	    </contact>
			<plugin filename="libgazebo_ros_bumper.so" name="bumper_plugin_0${num}">
				<bumperTopicName>bumper_0${num}</bumperTopicName>
				<frameName>body_0${num}</frameName>
			</plugin>
		</sensor>
	</gazebo>

	</macro>
	
	
	

	<macro name="body_above9" params="num nextNum">
	
	<link name="body_${num}">
		<collision> 
		  <origin xyz="${chassisLength/2 + jointOffset} 0 0" rpy="0 0 0"/> 
		  <geometry> 
		    <box size="${chassisLength} ${chassisWidth} ${chassisHeight}"/> 
		  </geometry> 
		</collision>
		<visual> 
		  <origin xyz="${chassisLength/2 + jointOffset} 0 0" rpy="0 0 0"/> 
		  <geometry> 
		    <box size="${chassisLength} ${chassisWidth} ${chassisHeight}"/> 
		  </geometry> 
		  <material name="green"/>
		</visual>
		<inertial> 
		  <origin xyz="${chassisLength/2 + jointOffset} 0 0" rpy="0 0 0"/> 
    	<mass value="${chassisMass}"/> 
    	<box_inertia m="${chassisMass}" x="${chassisLength}" y="${chassisWidth}" z="${chassisHeight}"/>
  	</inertial>
	</link>
	
	<gazebo reference="body_${num}">
  	<mu1 value="0.3"/>
  	<mu2 value="0.3"/>
  	<kp  value="10000000.0" />
  	<kd  value="1.0" />
  	<fdir1 value="1 0 0"/>
  	<material>Gazebo/Orange</material>
  	
  	<sensor name="body_${num}_bumper" type="contact">
			<always_on>true</always_on>
	    <update_rate>30</update_rate>
	    <contact>
	      <collision>body_${num}_collision</collision>
	    </contact>
			<plugin filename="libgazebo_ros_bumper.so" name="bumper_plugin_${num}">
				<bumperTopicName>bumper_${num}</bumperTopicName>
				<frameName>body_${num}</frameName>
			</plugin>
		</sensor>
	</gazebo>
	
	<joint name="joint_${num}" type="continuous">
		<parent link="body_${num}"/>
  	<child link="body_${nextNum}"/>
		<origin xyz="${chassisLength+2*jointOffset} 0 0" rpy="0 0 0" />
	 	<axis xyz="0 0 1" rpy="0 0 0" />
		<limit effort="100" velocity="1"/>
		<joint_properties damping="100.0" friction="0.0"/>
	</joint>

	<transmission name="trans_${num}">
		<type>transmission_interface/SimpleTransmission</type>
		<joint name="joint_${num}">
			<hardwareInterface>EffortJointInterface</hardwareInterface>
		</joint>
		<actuator name="motor_${num}">
		  <hardwareInterface>EffortJointInterface</hardwareInterface>
		  <mechanicalReduction>10</mechanicalReduction>
		</actuator>
	</transmission>

	</macro>
	
	<macro name="body_last_above9" params="num">
	
	<link name="body_${num}">
		<collision> 
		  <origin xyz="${chassisLength/2 + jointOffset} 0 0" rpy="0 0 0"/> 
		  <geometry> 
		    <box size="${chassisLength} ${chassisWidth} ${chassisHeight}"/> 
		  </geometry> 
		</collision>
		<visual> 
		  <origin xyz="${chassisLength/2 + jointOffset} 0 0" rpy="0 0 0"/> 
		  <geometry> 
		    <box size="${chassisLength} ${chassisWidth} ${chassisHeight}"/> 
		  </geometry> 
		  <material name="green"/>
		</visual>
		<inertial> 
		  <origin xyz="${chassisLength/2 + jointOffset} 0 0" rpy="0 0 0"/> 
    	<mass value="${chassisMass}"/> 
    	<box_inertia m="${chassisMass}" x="${chassisLength}" y="${chassisWidth}" z="${chassisHeight}"/>
  	</inertial>
	</link>
	
	<gazebo reference="body_${num}">
  	<mu1 value="0.3"/>
  	<mu2 value="0.3"/>
  	<kp  value="10000000.0" />
  	<kd  value="1.0" />
  	<fdir1 value="1 0 0"/>
  	<material>Gazebo/Red</material>
  	
  	<sensor name="body_${num}_bumper" type="contact">
			<always_on>true</always_on>
	    <update_rate>30</update_rate>
	    <contact>
	      <collision>body_${num}_collision</collision>
	    </contact>
			<plugin filename="libgazebo_ros_bumper.so" name="bumper_plugin_${num}">
				<bumperTopicName>bumper_${num}</bumperTopicName>
				<frameName>body_${num}</frameName>
			</plugin>
		</sensor>
	</gazebo>

	</macro>

</robot>
